Workbook

Sheet P&L
A1: BUSINESS PLAN UMATCH - P&L (REGIME DE COMPETÊNCIA)
A3: Categoria | B3: Unidade | C3: 05/2024 | D3: 06/2024 | E3: 07/2024 | F3: 08/2024 | G3: 09/2024 | H3: 10/2024 | I3: 11/2024 | J3: 12/2024 | K3: 01/2025 | L3: 02/2025 | M3: 03/2025 | N3: 04/2025 | O3: 05/2025 | P3: 06/2025 | Q3: 07/2025 | R3: 08/2025 | S3: 09/2025 | T3: 10/2025
A5: NAU | B5: Users
A6: Brazil | B6: Users
A7: EaM | B7: Users
A8: Affiliates & Events | B8: Users
A9: Ads | B9: Users
A10: Organic | B10: Users
A11: USA | B11: Users
A12: EaM | B12: Users
A13: Ads | B13: Users
A14: Organic | B14: Users
A16: CPA | B16: BRL
A17: Brazil | B17: BRL
... A22: Ads | B22: BRL
A24: Revenue | B24: BRL | C24: =C25+C42 | D24: =D25+D42 | E24: =E25+E42 | F24: =F25+F42 | G24: =G25+G42 | H24: =H25+H42 | I24: =I25+I42 | J24: =J25+J42 | ... T24: =T25+T42
A25: Revenue no Tax (total das receitas recebidas em conta) | B25: BRL | C25: =C29+C37 | D25: =D29+D37 | E25: =E29+E37 | F25: =F29+F37 | G25: =G29+G37 | H25: =H29+H37 | I25: =I29+I37 | J25: =J29+J37 | ... T25: =T29+T37
A26: Google (IAPHUB) | B26: BRL | C26: 0 | D26: 0 | E26: 0 | F26: 0 | G26: 0 | H26: 0 | I26: 0 | J26: 0 | K26: 0 | L26: 0 | M26: 0 | N26: 0 | O26: 0 | P26: 0 | Q26: 0 | R26: 0 | S26: 0 | T26: 0
A27: Google (IAPHUB) x 0.85 | B27: BRL | C27: =C26*0.85 | D27: =D26*0.85 | E27: =E26*0.85 | F27: =F26*0.85 | G27: =G26*0.85 | H27: =H26*0.85 | I27: =I26*0.85 | J27: =J26*0.85 | ... T27: =T26*0.85
A28: Δ(%) | B28: % | C28: 0 | D28: =IFERROR((D27-C27)/C27,0) | E28: =IFERROR((E27-D27)/D27,0) | F28: =IFERROR((F27-E27)/E27,0) | G28: =IFERROR((G27-F27)/F27,0) | H28: =IFERROR((H27-G27)/G27,0) | I28: =IFERROR((I27-H27)/H27,0) | J28: =IFERROR((J27-I27)/I27,0) | K28: =IFERROR((K27-J27)/J27,0) | ... T28: =IFERROR((T27-S27)/S27,0)
A29: Google | B29: BRL | C29: =SUMIFS(Extrato_Importado!$E:$E,Extrato_Importado!$H:$H,"2024-05",Extrato_Importado!$B:$B,"Google Play Net Revenue") | D29: =SUMIFS(Extrato_Importado!$E:$E,Extrato_Importado!$H:$H,"2024-06",Extrato_Importado!$B:$B,"Google Play Net Revenue") | E29: =SUMIFS(Extrato_Importado!$E:$E,Extrato_Importado!$H:$H,"2024-07",Extrato_Importado!$B:$B,"Google Play Net Revenue") | F29: =SUMIFS(Extrato_Importado!$E:$E,Extrato_Importado!$H:$H,"2024-08",Extrato_Importado!$B:$B,"Google Play Net Revenue") | G29: =SUMIFS(Extrato_Importado!$E:$E,Extrato_Importado!$H:$H,"2024-09",Extrato_Importado!$B:$B,"Google Play Net Revenue") | H29: =SUMIFS(Extrato_Importado!$E:$E,Extrato_Importado!$H:$H,"2024-10",Extrato_Importado!$B:$B,"Google Play Net Revenue") | I29: =SUMIFS(Extrato_Importado!$E:$E,Extrato_Importado!$H:$H,"2024-11",Extrato_Importado!$B:$B,"Google Play Net Revenue") | J29: =SUMIFS(Extrato_Importado!$E:$E,Extrato_Importado!$H:$H,"2024-12",Extrato_Importado!$B:$B,"Google Play Net Revenue") | K29: =SUMIFS(Extrato_Importado!$E:$E,Extrato_Importado!$H:$H,"2025-01",Extrato_Importado!$B:$B,"Google Play Net Revenue") | L29: =SUMIFS(Extrato_Importado!$E:$E,Extrato_Importado!$H:$H,"2025-02",Extrato_Importado!$B:$B,"Google Play Net Revenue") | M29: =SUMIFS(Extrato_Importado!$E:$E,Extrato_Importado!$H:$H,"2025-03",Extrato_Importado!$B:$B,"Google Play Net Revenue") | N29: =SUMIFS(Extrato_Importado!$E:$E,Extrato_Importado!$H:$H,"2025-04",Extrato_Importado!$B:$B,"Google Play Net Revenue") | O29: =SUMIFS(Extrato_Importado!$E:$E,Extrato_Importado!$H:$H,"2025-05",Extrato_Importado!$B:$B,"Google Play Net Revenue") | P29: =SUMIFS(Extrato_Importado!$E:$E,Extrato_Importado!$H:$H,"2025-06",Extrato_Importado!$B:$B,"Google Play Net Revenue") | Q29: =SUMIFS(Extrato_Importado!$E:$E,Extrato_Importado!$H:$H,"2025-07",Extrato_Importado!$B:$B,"Google Play Net Revenue") | R29: =SUMIFS(Extrato_Importado!$E:$E,Extrato_Importado!$H:$H,"2025-08",Extrato_Importado!$B:$B,"Google Play Net Revenue") | S29: =SUMIFS(Extrato_Importado!$E:$E,Extrato_Importado!$H:$H,"2025-09",Extrato_Importado!$B:$B,"Google Play Net Revenue") | T29: =SUMIFS(Extrato_Importado!$E:$E,Extrato_Importado!$H:$H,"2025-10",Extrato_Importado!$B:$B,"Google Play Net Revenue")
A30: Brazil | B30: BRL | C30: =SUMIFS(Extrato_Importado!$E:$E,Extrato_Importado!$H:$H,"2024-05",Extrato_Importado!$B:$B,"Google Play Net Revenue") | D30: =SUMIFS(Extrato_Importado!$E:$E,Extrato_Importado!$H:$H,"2024-06",Extrato_Importado!$B:$B,"Google Play Net Revenue") | E30: =SUMIFS(Extrato_Importado!$E:$E,Extrato_Importado!$H:$H,"2024-07",Extrato_Importado!$B:$B,"Google Play Net Revenue") | F30: =SUMIFS(Extrato_Importado!$E:$E,Extrato_Importado!$H:$H,"2024-08",Extrato_Importado!$B:$B,"Google Play Net Revenue") | G30: =SUMIFS(Extrato_Importado!$E:$E,Extrato_Importado!$H:$H,"2024-09",Extrato_Importado!$B:$B,"Google Play Net Revenue") | H30: =SUMIFS(Extrato_Importado!$E:$E,Extrato_Importado!$H:$H,"2024-10",Extrato_Importado!$B:$B,"Google Play Net Revenue") | I30: =SUMIFS(Extrato_Importado!$E:$E,Extrato_Importado!$H:$H,"2024-11",Extrato_Importado!$B:$B,"Google Play Net Revenue") | J30: =SUMIFS(Extrato_Importado!$E:$E,Extrato_Importado!$H:$H,"2024-12",Extrato_Importado!$B:$B,"Google Play Net Revenue") | K30: =SUMIFS(Extrato_Importado!$E:$E,Extrato_Importado!$H:$H,"2025-01",Extrato_Importado!$B:$B,"Google Play Net Revenue") | L30: =SUMIFS(Extrato_Importado!$E:$E,Extrato_Importado!$H:$H,"2025-02",Extrato_Importado!$B:$B,"Google Play Net Revenue") | M30: =SUMIFS(Extrato_Importado!$E:$E,Extrato_Importado!$H:$H,"2025-03",Extrato_Importado!$B:$B,"Google Play Net Revenue") | N30: =SUMIFS(Extrato_Importado!$E:$E,Extrato_Importado!$H:$H,"2025-04",Extrato_Importado!$B:$B,"Google Play Net Revenue") | O30: =SUMIFS(Extrato_Importado!$E:$E,Extrato_Importado!$H:$H,"2025-05",Extrato_Importado!$B:$B,"Google Play Net Revenue") | P30: =SUMIFS(Extrato_Importado!$E:$E,Extrato_Importado!$H:$H,"2025-06",Extrato_Importado!$B:$B,"Google Play Net Revenue") | Q30: =SUMIFS(Extrato_Importado!$E:$E,Extrato_Importado!$H:$H,"2025-07",Extrato_Importado!$B:$B,"Google Play Net Revenue") | R30: =SUMIFS(Extrato_Importado!$E:$E,Extrato_Importado!$H:$H,"2025-08",Extrato_Importado!$B:$B,"Google Play Net Revenue") | S30: =SUMIFS(Extrato_Importado!$E:$E,Extrato_Importado!$H:$H,"2025-09",Extrato_Importado!$B:$B,"Google Play Net Revenue") | T30: =SUMIFS(Extrato_Importado!$E:$E,Extrato_Importado!$H:$H,"2025-10",Extrato_Importado!$B:$B,"Google Play Net Revenue")
A31: Brazil Margin (%) | B31: % | C31: =IFERROR(C30/C29,0) | D31: =IFERROR(D30/D29,0) | E31: =IFERROR(E30/E29,0) | F31: =IFERROR(F30/F29,0) | G31: =IFERROR(G30/G29,0) | H31: =IFERROR(H30/H29,0) | I31: =IFERROR(I30/I29,0) | J31: =IFERROR(J30/J29,0) | ... T31: =IFERROR(T30/T29,0)
A32: USA | B32: BRL | C32: =SUMIFS(Extrato_Importado!$E:$E,Extrato_Importado!$H:$H,"2024-05",Extrato_Importado!$B:$B,"Google Play Net Revenue") | D32: =SUMIFS(Extrato_Importado!$E:$E,Extrato_Importado!$H:$H,"2024-06",Extrato_Importado!$B:$B,"Google Play Net Revenue") | E32: =SUMIFS(Extrato_Importado!$E:$E,Extrato_Importado!$H:$H,"2024-07",Extrato_Importado!$B:$B,"Google Play Net Revenue") | F32: =SUMIFS(Extrato_Importado!$E:$E,Extrato_Importado!$H:$H,"2024-08",Extrato_Importado!$B:$B,"Google Play Net Revenue") | G32: =SUMIFS(Extrato_Importado!$E:$E,Extrato_Importado!$H:$H,"2024-09",Extrato_Importado!$B:$B,"Google Play Net Revenue") | H32: =SUMIFS(Extrato_Importado!$E:$E,Extrato_Importado!$H:$H,"2024-10",Extrato_Importado!$B:$B,"Google Play Net Revenue") | I32: =SUMIFS(Extrato_Importado!$E:$E,Extrato_Importado!$H:$H,"2024-11",Extrato_Importado!$B:$B,"Google Play Net Revenue") | J32: =SUMIFS(Extrato_Importado!$E:$E,Extrato_Importado!$H:$H,"2024-12",Extrato_Importado!$B:$B,"Google Play Net Revenue") | K32: =SUMIFS(Extrato_Importado!$E:$E,Extrato_Importado!$H:$H,"2025-01",Extrato_Importado!$B:$B,"Google Play Net Revenue") | L32: =SUMIFS(Extrato_Importado!$E:$E,Extrato_Importado!$H:$H,"2025-02",Extrato_Importado!$B:$B,"Google Play Net Revenue") | M32: =SUMIFS(Extrato_Importado!$E:$E,Extrato_Importado!$H:$H,"2025-03",Extrato_Importado!$B:$B,"Google Play Net Revenue") | N32: =SUMIFS(Extrato_Importado!$E:$E,Extrato_Importado!$H:$H,"2025-04",Extrato_Importado!$B:$B,"Google Play Net Revenue") | O32: =SUMIFS(Extrato_Importado!$E:$E,Extrato_Importado!$H:$H,"2025-05",Extrato_Importado!$B:$B,"Google Play Net Revenue") | P32: =SUMIFS(Extrato_Importado!$E:$E,Extrato_Importado!$H:$H,"2025-06",Extrato_Importado!$B:$B,"Google Play Net Revenue") | Q32: =SUMIFS(Extrato_Importado!$E:$E,Extrato_Importado!$H:$H,"2025-07",Extrato_Importado!$B:$B,"Google Play Net Revenue") | R32: =SUMIFS(Extrato_Importado!$E:$E,Extrato_Importado!$H:$H,"2025-08",Extrato_Importado!$B:$B,"Google Play Net Revenue") | S32: =SUMIFS(Extrato_Importado!$E:$E,Extrato_Importado!$H:$H,"2025-09",Extrato_Importado!$B:$B,"Google Play Net Revenue") | T32: =SUMIFS(Extrato_Importado!$E:$E,Extrato_Importado!$H:$H,"2025-10",Extrato_Importado!$B:$B,"Google Play Net Revenue")
A33: USA Margin (%) | B33: % | C33: =IFERROR(C32/C29,0) | D33: =IFERROR(D32/D29,0) | E33: =IFERROR(E32/E29,0) | F33: =IFERROR(F32/F29,0) | G33: =IFERROR(G32/G29,0) | H33: =IFERROR(H32/H29,0) | I33: =IFERROR(I32/I29,0) | J33: =IFERROR(J32/J29,0) | ... T33: =IFERROR(T32/T29,0)
A34: Apple (IAPHUB) | B34: BRL | C34: 0 | D34: 0 | E34: 0 | F34: 0 | G34: 0 | H34: 0 | I34: 0 | J34: 0 | K34: 0 | L34: 0 | M34: 0 | N34: 0 | O34: 0 | P34: 0 | Q34: 0 | R34: 0 | S34: 0 | T34: 0
A35: Apple (IAPHUB) x 0.85 | B35: BRL | C35: =C34*0.85 | D35: =D34*0.85 | E35: =E34*0.85 | F35: =F34*0.85 | G35: =G34*0.85 | H35: =H34*0.85 | I35: =I34*0.85 | J35: =J34*0.85 | ... T35: =T34*0.85
A36: Δ(%) | B36: % | C36: 0 | D36: =IFERROR((D35-C35)/C35,0) | E36: =IFERROR((E35-D35)/D35,0) | F36: =IFERROR((F35-E35)/E35,0) | G36: =IFERROR((G35-F35)/F35,0) | H36: =IFERROR((H35-G35)/G35,0) | I36: =IFERROR((I35-H35)/H35,0) | J36: =IFERROR((J35-I35)/I35,0) | K36: =IFERROR((K35-J35)/J35,0) | ... T36: =IFERROR((T35-S35)/S35,0)
A37: Apple | B37: BRL | C37: =SUMIFS(Extrato_Importado!$E:$E,Extrato_Importado!$H:$H,"2024-05",Extrato_Importado!$B:$B,"App Store Net Revenue") | D37: =SUMIFS(Extrato_Importado!$E:$E,Extrato_Importado!$H:$H,"2024-06",Extrato_Importado!$B:$B,"App Store Net Revenue") | E37: =SUMIFS(Extrato_Importado!$E:$E,Extrato_Importado!$H:$H,"2024-07",Extrato_Importado!$B:$B,"App Store Net Revenue") | F37: =SUMIFS(Extrato_Importado!$E:$E,Extrato_Importado!$H:$H,"2024-08",Extrato_Importado!$B:$B,"App Store Net Revenue") | G37: =SUMIFS(Extrato_Importado!$E:$E,Extrato_Importado!$H:$H,"2024-09",Extrato_Importado!$B:$B,"App Store Net Revenue") | H37: =SUMIFS(Extrato_Importado!$E:$E,Extrato_Importado!$H:$H,"2024-10",Extrato_Importado!$B:$B,"App Store Net Revenue") | I37: =SUMIFS(Extrato_Importado!$E:$E,Extrato_Importado!$H:$H,"2024-11",Extrato_Importado!$B:$B,"App Store Net Revenue") | J37: =SUMIFS(Extrato_Importado!$E:$E,Extrato_Importado!$H:$H,"2024-12",Extrato_Importado!$B:$B,"App Store Net Revenue") | K37: =SUMIFS(Extrato_Importado!$E:$E,Extrato_Importado!$H:$H,"2025-01",Extrato_Importado!$B:$B,"App Store Net Revenue") | L37: =SUMIFS(Extrato_Importado!$E:$E,Extrato_Importado!$H:$H,"2025-02",Extrato_Importado!$B:$B,"App Store Net Revenue") | M37: =SUMIFS(Extrato_Importado!$E:$E,Extrato_Importado!$H:$H,"2025-03",Extrato_Importado!$B:$B,"App Store Net Revenue") | N37: =SUMIFS(Extrato_Importado!$E:$E,Extrato_Importado!$H:$H,"2025-04",Extrato_Importado!$B:$B,"App Store Net Revenue") | O37: =SUMIFS(Extrato_Importado!$E:$E,Extrato_Importado!$H:$H,"2025-05",Extrato_Importado!$B:$B,"App Store Net Revenue") | P37: =SUMIFS(Extrato_Importado!$E:$E,Extrato_Importado!$H:$H,"2025-06",Extrato_Importado!$B:$B,"App Store Net Revenue") | Q37: =SUMIFS(Extrato_Importado!$E:$E,Extrato_Importado!$H:$H,"2025-07",Extrato_Importado!$B:$B,"App Store Net Revenue") | R37: =SUMIFS(Extrato_Importado!$E:$E,Extrato_Importado!$H:$H,"2025-08",Extrato_Importado!$B:$B,"App Store Net Revenue") | S37: =SUMIFS(Extrato_Importado!$E:$E,Extrato_Importado!$H:$H,"2025-09",Extrato_Importado!$B:$B,"App Store Net Revenue") | T37: =SUMIFS(Extrato_Importado!$E:$E,Extrato_Importado!$H:$H,"2025-10",Extrato_Importado!$B:$B,"App Store Net Revenue")
A38: Brazil | B38: BRL | C38: =SUMIFS(Extrato_Importado!$E:$E,Extrato_Importado!$H:$H,"2024-05",Extrato_Importado!$B:$B,"App Store Net Revenue") | D38: =SUMIFS(Extrato_Importado!$E:$E,Extrato_Importado!$H:$H,"2024-06",Extrato_Importado!$B:$B,"App Store Net Revenue") | E38: =SUMIFS(Extrato_Importado!$E:$E,Extrato_Importado!$H:$H,"2024-07",Extrato_Importado!$B:$B,"App Store Net Revenue") | F38: =SUMIFS(Extrato_Importado!$E:$E,Extrato_Importado!$H:$H,"2024-08",Extrato_Importado!$B:$B,"App Store Net Revenue") | G38: =SUMIFS(Extrato_Importado!$E:$E,Extrato_Importado!$H:$H,"2024-09",Extrato_Importado!$B:$B,"App Store Net Revenue") | H38: =SUMIFS(Extrato_Importado!$E:$E,Extrato_Importado!$H:$H,"2024-10",Extrato_Importado!$B:$B,"App Store Net Revenue") | I38: =SUMIFS(Extrato_Importado!$E:$E,Extrato_Importado!$H:$H,"2024-11",Extrato_Importado!$B:$B,"App Store Net Revenue") | J38: =SUMIFS(Extrato_Importado!$E:$E,Extrato_Importado!$H:$H,"2024-12",Extrato_Importado!$B:$B,"App Store Net Revenue") | K38: =SUMIFS(Extrato_Importado!$E:$E,Extrato_Importado!$H:$H,"2025-01",Extrato_Importado!$B:$B,"App Store Net Revenue") | L38: =SUMIFS(Extrato_Importado!$E:$E,Extrato_Importado!$H:$H,"2025-02",Extrato_Importado!$B:$B,"App Store Net Revenue") | M38: =SUMIFS(Extrato_Importado!$E:$E,Extrato_Importado!$H:$H,"2025-03",Extrato_Importado!$B:$B,"App Store Net Revenue") | N38: =SUMIFS(Extrato_Importado!$E:$E,Extrato_Importado!$H:$H,"2025-04",Extrato_Importado!$B:$B,"App Store Net Revenue") | O38: =SUMIFS(Extrato_Importado!$E:$E,Extrato_Importado!$H:$H,"2025-05",Extrato_Importado!$B:$B,"App Store Net Revenue") | P38: =SUMIFS(Extrato_Importado!$E:$E,Extrato_Importado!$H:$H,"2025-06",Extrato_Importado!$B:$B,"App Store Net Revenue") | Q38: =SUMIFS(Extrato_Importado!$E:$E,Extrato_Importado!$H:$H,"2025-07",Extrato_Importado!$B:$B,"App Store Net Revenue") | R38: =SUMIFS(Extrato_Importado!$E:$E,Extrato_Importado!$H:$H,"2025-08",Extrato_Importado!$B:$B,"App Store Net Revenue") | S38: =SUMIFS(Extrato_Importado!$E:$E,Extrato_Importado!$H:$H,"2025-09",Extrato_Importado!$B:$B,"App Store Net Revenue") | T38: =SUMIFS(Extrato_Importado!$E:$E,Extrato_Importado!$H:$H,"2025-10",Extrato_Importado!$B:$B,"App Store Net Revenue")
A39: Brazil Margin (%) | B39: % | C39: =IFERROR(C38/C37,0) | D39: =IFERROR(D38/D37,0) | E39: =IFERROR(E38/E37,0) | F39: =IFERROR(F38/F37,0) | G39: =IFERROR(G38/G37,0) | H39: =IFERROR(H38/H37,0) | I39: =IFERROR(I38/I37,0) | J39: =IFERROR(J38/J37,0) | ... T39: =IFERROR(T38/T37,0)
A40: USA | B40: BRL | C40: =SUMIFS(Extrato_Importado!$E:$E,Extrato_Importado!$H:$H,"2024-05",Extrato_Importado!$B:$B,"App Store Net Revenue") | D40: =SUMIFS(Extrato_Importado!$E:$E,Extrato_Importado!$H:$H,"2024-06",Extrato_Importado!$B:$B,"App Store Net Revenue") | E40: =SUMIFS(Extrato_Importado!$E:$E,Extrato_Importado!$H:$H,"2024-07",Extrato_Importado!$B:$B,"App Store Net Revenue") | F40: =SUMIFS(Extrato_Importado!$E:$E,Extrato_Importado!$H:$H,"2024-08",Extrato_Importado!$B:$B,"App Store Net Revenue") | G40: =SUMIFS(Extrato_Importado!$E:$E,Extrato_Importado!$H:$H,"2024-09",Extrato_Importado!$B:$B,"App Store Net Revenue") | H40: =SUMIFS(Extrato_Importado!$E:$E,Extrato_Importado!$H:$H,"2024-10",Extrato_Importado!$B:$B,"App Store Net Revenue") | I40: =SUMIFS(Extrato_Importado!$E:$E,Extrato_Importado!$H:$H,"2024-11",Extrato_Importado!$B:$B,"App Store Net Revenue") | J40: =SUMIFS(Extrato_Importado!$E:$E,Extrato_Importado!$H:$H,"2024-12",Extrato_Importado!$B:$B,"App Store Net Revenue") | K40: =SUMIFS(Extrato_Importado!$E:$E,Extrato_Importado!$H:$H,"2025-01",Extrato_Importado!$B:$B,"App Store Net Revenue") | L40: =SUMIFS(Extrato_Importado!$E:$E,Extrato_Importado!$H:$H,"2025-02",Extrato_Importado!$B:$B,"App Store Net Revenue") | M40: =SUMIFS(Extrato_Importado!$E:$E,Extrato_Importado!$H:$H,"2025-03",Extrato_Importado!$B:$B,"App Store Net Revenue") | N40: =SUMIFS(Extrato_Importado!$E:$E,Extrato_Importado!$H:$H,"2025-04",Extrato_Importado!$B:$B,"App Store Net Revenue") | O40: =SUMIFS(Extrato_Importado!$E:$E,Extrato_Importado!$H:$H,"2025-05",Extrato_Importado!$B:$B,"App Store Net Revenue") | P40: =SUMIFS(Extrato_Importado!$E:$E,Extrato_Importado!$H:$H,"2025-06",Extrato_Importado!$B:$B,"App Store Net Revenue") | Q40: =SUMIFS(Extrato_Importado!$E:$E,Extrato_Importado!$H:$H,"2025-07",Extrato_Importado!$B:$B,"App Store Net Revenue") | R40: =SUMIFS(Extrato_Importado!$E:$E,Extrato_Importado!$H:$H,"2025-08",Extrato_Importado!$B:$B,"App Store Net Revenue") | S40: =SUMIFS(Extrato_Importado!$E:$E,Extrato_Importado!$H:$H,"2025-09",Extrato_Importado!$B:$B,"App Store Net Revenue") | T40: =SUMIFS(Extrato_Importado!$E:$E,Extrato_Importado!$H:$H,"2025-10",Extrato_Importado!$B:$B,"App Store Net Revenue")
A41: USA Margin (%) | B41: % | C41: =IFERROR(C40/C37,0) | D41: =IFERROR(D40/D37,0) | E41: =IFERROR(E40/E37,0) | F41: =IFERROR(F40/F37,0) | G41: =IFERROR(G40/G37,0) | H41: =IFERROR(H40/H37,0) | I41: =IFERROR(I40/I37,0) | J41: =IFERROR(J40/J37,0) | ... T41: =IFERROR(T40/T37,0)
A42: Invest Income (rendimento de aplicação & cashback) | B42: BRL | C42: =SUMIFS(Extrato_Importado!$E:$E,Extrato_Importado!$H:$H,"2024-05",Extrato_Importado!$B:$B,"Rendimentos de Aplicações") | D42: =SUMIFS(Extrato_Importado!$E:$E,Extrato_Importado!$H:$H,"2024-06",Extrato_Importado!$B:$B,"Rendimentos de Aplicações") | E42: =SUMIFS(Extrato_Importado!$E:$E,Extrato_Importado!$H:$H,"2024-07",Extrato_Importado!$B:$B,"Rendimentos de Aplicações") | F42: =SUMIFS(Extrato_Importado!$E:$E,Extrato_Importado!$H:$H,"2024-08",Extrato_Importado!$B:$B,"Rendimentos de Aplicações") | G42: =SUMIFS(Extrato_Importado!$E:$E,Extrato_Importado!$H:$H,"2024-09",Extrato_Importado!$B:$B,"Rendimentos de Aplicações") | H42: =SUMIFS(Extrato_Importado!$E:$E,Extrato_Importado!$H:$H,"2024-10",Extrato_Importado!$B:$B,"Rendimentos de Aplicações") | I42: =SUMIFS(Extrato_Importado!$E:$E,Extrato_Importado!$H:$H,"2024-11",Extrato_Importado!$B:$B,"Rendimentos de Aplicações") | J42: =SUMIFS(Extrato_Importado!$E:$E,Extrato_Importado!$H:$H,"2024-12",Extrato_Importado!$B:$B,"Rendimentos de Aplicações") | K42: =SUMIFS(Extrato_Importado!$E:$E,Extrato_Importado!$H:$H,"2025-01",Extrato_Importado!$B:$B,"Rendimentos de Aplicações") | L42: =SUMIFS(Extrato_Importado!$E:$E,Extrato_Importado!$H:$H,"2025-02",Extrato_Importado!$B:$B,"Rendimentos de Aplicações") | M42: =SUMIFS(Extrato_Importado!$E:$E,Extrato_Importado!$H:$H,"2025-03",Extrato_Importado!$B:$B,"Rendimentos de Aplicações") | N42: =SUMIFS(Extrato_Importado!$E:$E,Extrato_Importado!$H:$H,"2025-04",Extrato_Importado!$B:$B,"Rendimentos de Aplicações") | O42: =SUMIFS(Extrato_Importado!$E:$E,Extrato_Importado!$H:$H,"2025-05",Extrato_Importado!$B:$B,"Rendimentos de Aplicações") | P42: =SUMIFS(Extrato_Importado!$E:$E,Extrato_Importado!$H:$H,"2025-06",Extrato_Importado!$B:$B,"Rendimentos de Aplicações") | Q42: =SUMIFS(Extrato_Importado!$E:$E,Extrato_Importado!$H:$H,"2025-07",Extrato_Importado!$B:$B,"Rendimentos de Aplicações") | R42: =SUMIFS(Extrato_Importado!$E:$E,Extrato_Importado!$H:$H,"2025-08",Extrato_Importado!$B:$B,"Rendimentos de Aplicações") | S42: =SUMIFS(Extrato_Importado!$E:$E,Extrato_Importado!$H:$H,"2025-09",Extrato_Importado!$B:$B,"Rendimentos de Aplicações") | T42: =SUMIFS(Extrato_Importado!$E:$E,Extrato_Importado!$H:$H,"2025-10",Extrato_Importado!$B:$B,"Rendimentos de Aplicações")
A44: Costs of Revenue | B44: BRL | C44: =C45+C46 | D44: =D45+D46 | E44: =E45+E46 | F44: =F45+F46 | G44: =G45+G46 | H44: =H45+H46 | I44: =I45+I46 | J44: =J45+J46 | ... T44: =T45+T46
A45: Payment Processing Expenses (despesas de processamento de pagamento) | B45: BRL | C45: =C25*0.1765 | D45: =D25*0.1765 | E45: =E25*0.1765 | F45: =F25*0.1765 | G45: =G25*0.1765 | H45: =H25*0.1765 | I45: =I25*0.1765 | J45: =J25*0.1765 | ... T45: =T25*0.1765
A46: COGS (CMV) | B46: BRL | C46: =SUM(C47:C52) | D46: =SUM(D47:D52) | E46: =SUM(E47:E52) | F46: =SUM(F47:F52) | G46: =SUM(G47:G52) | H46: =SUM(H47:H52) | I46: =SUM(I47:I52) | J46: =SUM(J47:J52) | ... T46: =SUM(T47:T52)
A47: AWS | B47: BRL | C47: =SUMIFS(Extrato_Importado!$E:$E,Extrato_Importado!$H:$H,"2024-05",Extrato_Importado!$B:$B,"Web Services Expenses",Extrato_Importado!$C:$C,"*AWS*") | D47: =SUMIFS(Extrato_Importado!$E:$E,Extrato_Importado!$H:$H,"2024-06",Extrato_Importado!$B:$B,"Web Services Expenses",Extrato_Importado!$C:$C,"*AWS*") | E47: =SUMIFS(Extrato_Importado!$E:$E,Extrato_Importado!$H:$H,"2024-07",Extrato_Importado!$B:$B,"Web Services Expenses",Extrato_Importado!$C:$C,"*AWS*") | F47: =SUMIFS(Extrato_Importado!$E:$E,Extrato_Importado!$H:$H,"2024-08",Extrato_Importado!$B:$B,"Web Services Expenses",Extrato_Importado!$C:$C,"*AWS*") | G47: =SUMIFS(Extrato_Importado!$E:$E,Extrato_Importado!$H:$H,"2024-09",Extrato_Importado!$B:$B,"Web Services Expenses",Extrato_Importado!$C:$C,"*AWS*") | H47: =SUMIFS(Extrato_Importado!$E:$E,Extrato_Importado!$H:$H,"2024-10",Extrato_Importado!$B:$B,"Web Services Expenses",Extrato_Importado!$C:$C,"*AWS*") | I47: =SUMIFS(Extrato_Importado!$E:$E,Extrato_Importado!$H:$H,"2024-11",Extrato_Importado!$B:$B,"Web Services Expenses",Extrato_Importado!$C:$C,"*AWS*") | J47: =SUMIFS(Extrato_Importado!$E:$E,Extrato_Importado!$H:$H,"2024-12",Extrato_Importado!$B:$B,"Web Services Expenses",Extrato_Importado!$C:$C,"*AWS*") | K47: =SUMIFS(Extrato_Importado!$E:$E,Extrato_Importado!$H:$H,"2025-01",Extrato_Importado!$B:$B,"Web Services Expenses",Extrato_Importado!$C:$C,"*AWS*") | L47: =SUMIFS(Extrato_Importado!$E:$E,Extrato_Importado!$H:$H,"2025-02",Extrato_Importado!$B:$B,"Web Services Expenses",Extrato_Importado!$C:$C,"*AWS*") | M47: =SUMIFS(Extrato_Importado!$E:$E,Extrato_Importado!$H:$H,"2025-03",Extrato_Importado!$B:$B,"Web Services Expenses",Extrato_Importado!$C:$C,"*AWS*") | N47: =SUMIFS(Extrato_Importado!$E:$E,Extrato_Importado!$H:$H,"2025-04",Extrato_Importado!$B:$B,"Web Services Expenses",Extrato_Importado!$C:$C,"*AWS*") | O47: =SUMIFS(Extrato_Importado!$E:$E,Extrato_Importado!$H:$H,"2025-05",Extrato_Importado!$B:$B,"Web Services Expenses",Extrato_Importado!$C:$C,"*AWS*") | P47: =SUMIFS(Extrato_Importado!$E:$E,Extrato_Importado!$H:$H,"2025-06",Extrato_Importado!$B:$B,"Web Services Expenses",Extrato_Importado!$C:$C,"*AWS*") | Q47: =SUMIFS(Extrato_Importado!$E:$E,Extrato_Importado!$H:$H,"2025-07",Extrato_Importado!$B:$B,"Web Services Expenses",Extrato_Importado!$C:$C,"*AWS*") | R47: =SUMIFS(Extrato_Importado!$E:$E,Extrato_Importado!$H:$H,"2025-08",Extrato_Importado!$B:$B,"Web Services Expenses",Extrato_Importado!$C:$C,"*AWS*") | S47: =SUMIFS(Extrato_Importado!$E:$E,Extrato_Importado!$H:$H,"2025-09",Extrato_Importado!$B:$B,"Web Services Expenses",Extrato_Importado!$C:$C,"*AWS*") | T47: =SUMIFS(Extrato_Importado!$E:$E,Extrato_Importado!$H:$H,"2025-10",Extrato_Importado!$B:$B,"Web Services Expenses",Extrato_Importado!$C:$C,"*AWS*")
A48: Cloudflare | B48: BRL | C48: =SUMIFS(Extrato_Importado!$E:$E,Extrato_Importado!$H:$H,"2024-05",Extrato_Importado!$B:$B,"Web Services Expenses",Extrato_Importado!$C:$C,"*Cloudflare*") | D48: =SUMIFS(Extrato_Importado!$E:$E,Extrato_Importado!$H:$H,"2024-06",Extrato_Importado!$B:$B,"Web Services Expenses",Extrato_Importado!$C:$C,"*Cloudflare*") | E48: =SUMIFS(Extrato_Importado!$E:$E,Extrato_Importado!$H:$H,"2024-07",Extrato_Importado!$B:$B,"Web Services Expenses",Extrato_Importado!$C:$C,"*Cloudflare*") | F48: =SUMIFS(Extrato_Importado!$E:$E,Extrato_Importado!$H:$H,"2024-08",Extrato_Importado!$B:$B,"Web Services Expenses",Extrato_Importado!$C:$C,"*Cloudflare*") | G48: =SUMIFS(Extrato_Importado!$E:$E,Extrato_Importado!$H:$H,"2024-09",Extrato_Importado!$B:$B,"Web Services Expenses",Extrato_Importado!$C:$C,"*Cloudflare*") | H48: =SUMIFS(Extrato_Importado!$E:$E,Extrato_Importado!$H:$H,"2024-10",Extrato_Importado!$B:$B,"Web Services Expenses",Extrato_Importado!$C:$C,"*Cloudflare*") | I48: =SUMIFS(Extrato_Importado!$E:$E,Extrato_Importado!$H:$H,"2024-11",Extrato_Importado!$B:$B,"Web Services Expenses",Extrato_Importado!$C:$C,"*Cloudflare*") | J48: =SUMIFS(Extrato_Importado!$E:$E,Extrato_Importado!$H:$H,"2024-12",Extrato_Importado!$B:$B,"Web Services Expenses",Extrato_Importado!$C:$C,"*Cloudflare*") | K48: =SUMIFS(Extrato_Importado!$E:$E,Extrato_Importado!$H:$H,"2025-01",Extrato_Importado!$B:$B,"Web Services Expenses",Extrato_Importado!$C:$C,"*Cloudflare*") | L48: =SUMIFS(Extrato_Importado!$E:$E,Extrato_Importado!$H:$H,"2025-02",Extrato_Importado!$B:$B,"Web Services Expenses",Extrato_Importado!$C:$C,"*Cloudflare*") | M48: =SUMIFS(Extrato_Importado!$E:$E,Extrato_Importado!$H:$H,"2025-03",Extrato_Importado!$B:$B,"Web Services Expenses",Extrato_Importado!$C:$C,"*Cloudflare*") | N48: =SUMIFS(Extrato_Importado!$E:$E,Extrato_Importado!$H:$H,"2025-04",Extrato_Importado!$B:$B,"Web Services Expenses",Extrato_Importado!$C:$C,"*Cloudflare*") | O48: =SUMIFS(Extrato_Importado!$E:$E,Extrato_Importado!$H:$H,"2025-05",Extrato_Importado!$B:$B,"Web Services Expenses",Extrato_Importado!$C:$C,"*Cloudflare*") | P48: =SUMIFS(Extrato_Importado!$E:$E,Extrato_Importado!$H:$H,"2025-06",Extrato_Importado!$B:$B,"Web Services Expenses",Extrato_Importado!$C:$C,"*Cloudflare*") | Q48: =SUMIFS(Extrato_Importado!$E:$E,Extrato_Importado!$H:$H,"2025-07",Extrato_Importado!$B:$B,"Web Services Expenses",Extrato_Importado!$C:$C,"*Cloudflare*") | R48: =SUMIFS(Extrato_Importado!$E:$E,Extrato_Importado!$H:$H,"2025-08",Extrato_Importado!$B:$B,"Web Services Expenses",Extrato_Importado!$C:$C,"*Cloudflare*") | S48: =SUMIFS(Extrato_Importado!$E:$E,Extrato_Importado!$H:$H,"2025-09",Extrato_Importado!$B:$B,"Web Services Expenses",Extrato_Importado!$C:$C,"*Cloudflare*") | T48: =SUMIFS(Extrato_Importado!$E:$E,Extrato_Importado!$H:$H,"2025-10",Extrato_Importado!$B:$B,"Web Services Expenses",Extrato_Importado!$C:$C,"*Cloudflare*")
A49: Heroku | B49: BRL | C49: =SUMIFS(Extrato_Importado!$E:$E,Extrato_Importado!$H:$H,"2024-05",Extrato_Importado!$B:$B,"Web Services Expenses",Extrato_Importado!$C:$C,"*Heroku*") | D49: =SUMIFS(Extrato_Importado!$E:$E,Extrato_Importado!$H:$H,"2024-06",Extrato_Importado!$B:$B,"Web Services Expenses",Extrato_Importado!$C:$C,"*Heroku*") | E49: =SUMIFS(Extrato_Importado!$E:$E,Extrato_Importado!$H:$H,"2024-07",Extrato_Importado!$B:$B,"Web Services Expenses",Extrato_Importado!$C:$C,"*Heroku*") | F49: =SUMIFS(Extrato_Importado!$E:$E,Extrato_Importado!$H:$H,"2024-08",Extrato_Importado!$B:$B,"Web Services Expenses",Extrato_Importado!$C:$C,"*Heroku*") | G49: =SUMIFS(Extrato_Importado!$E:$E,Extrato_Importado!$H:$H,"2024-09",Extrato_Importado!$B:$B,"Web Services Expenses",Extrato_Importado!$C:$C,"*Heroku*") | H49: =SUMIFS(Extrato_Importado!$E:$E,Extrato_Importado!$H:$H,"2024-10",Extrato_Importado!$B:$B,"Web Services Expenses",Extrato_Importado!$C:$C,"*Heroku*") | I49: =SUMIFS(Extrato_Importado!$E:$E,Extrato_Importado!$H:$H,"2024-11",Extrato_Importado!$B:$B,"Web Services Expenses",Extrato_Importado!$C:$C,"*Heroku*") | J49: =SUMIFS(Extrato_Importado!$E:$E,Extrato_Importado!$H:$H,"2024-12",Extrato_Importado!$B:$B,"Web Services Expenses",Extrato_Importado!$C:$C,"*Heroku*") | K49: =SUMIFS(Extrato_Importado!$E:$E,Extrato_Importado!$H:$H,"2025-01",Extrato_Importado!$B:$B,"Web Services Expenses",Extrato_Importado!$C:$C,"*Heroku*") | L49: =SUMIFS(Extrato_Importado!$E:$E,Extrato_Importado!$H:$H,"2025-02",Extrato_Importado!$B:$B,"Web Services Expenses",Extrato_Importado!$C:$C,"*Heroku*") | M49: =SUMIFS(Extrato_Importado!$E:$E,Extrato_Importado!$H:$H,"2025-03",Extrato_Importado!$B:$B,"Web Services Expenses",Extrato_Importado!$C:$C,"*Heroku*") | N49: =SUMIFS(Extrato_Importado!$E:$E,Extrato_Importado!$H:$H,"2025-04",Extrato_Importado!$B:$B,"Web Services Expenses",Extrato_Importado!$C:$C,"*Heroku*") | O49: =SUMIFS(Extrato_Importado!$E:$E,Extrato_Importado!$H:$H,"2025-05",Extrato_Importado!$B:$B,"Web Services Expenses",Extrato_Importado!$C:$C,"*Heroku*") | P49: =SUMIFS(Extrato_Importado!$E:$E,Extrato_Importado!$H:$H,"2025-06",Extrato_Importado!$B:$B,"Web Services Expenses",Extrato_Importado!$C:$C,"*Heroku*") | Q49: =SUMIFS(Extrato_Importado!$E:$E,Extrato_Importado!$H:$H,"2025-07",Extrato_Importado!$B:$B,"Web Services Expenses",Extrato_Importado!$C:$C,"*Heroku*") | R49: =SUMIFS(Extrato_Importado!$E:$E,Extrato_Importado!$H:$H,"2025-08",Extrato_Importado!$B:$B,"Web Services Expenses",Extrato_Importado!$C:$C,"*Heroku*") | S49: =SUMIFS(Extrato_Importado!$E:$E,Extrato_Importado!$H:$H,"2025-09",Extrato_Importado!$B:$B,"Web Services Expenses",Extrato_Importado!$C:$C,"*Heroku*") | T49: =SUMIFS(Extrato_Importado!$E:$E,Extrato_Importado!$H:$H,"2025-10",Extrato_Importado!$B:$B,"Web Services Expenses",Extrato_Importado!$C:$C,"*Heroku*")
...

Sheet Inputs
A1: DADOS DE ENTRADA - BUSINESS PLAN UMATCH
A3: Seção | B3: Parâmetro | C3: Valor | D3: Unidade | E3: Observações
A4: Receita | B4: Taxa Apple/Google | C4: 0.85 | D4: % | E4: Receita líquida após desconto de 15%
A5: Receita | B5: Receita Bruta = Líquida / 0.85 | C5: =C4/C4 | D5: Fórmula | E5: Cálculo automático
A7: Custos | B7: COGS - AWS | D7: R$ | E7: Custo AWS (editável)
A8: Custos | B8: COGS - Cloudflare | D8: R$ | E8: Custo Cloudflare (editável)
A9: Custos | B9: COGS - Heroku | D9: R$ | E9: Custo Heroku (editável)
A10: Custos | B10: COGS - IAPHUB | D10: R$ | E10: Custo IAPHUB (editável)
A11: Custos | B11: COGS - MailGun | D11: R$ | E11: Custo MailGun (editável)
A12: Custos | B12: COGS - AWS SES | D12: R$ | E12: Custo AWS SES (editável)
A14: SG&A | B14: Marketing | D14: R$ | E14: Despesas de Marketing (editável)
A15: SG&A | B15: Wages | D15: R$ | E15: Salários e Pró-labore (editável)
A16: SG&A | B16: Tech Support & Services | D16: R$ | E16: Serviços de tecnologia (editável)
A18: Importação | B18: Status Importação | C18: Pendente | D18: Status | E18: Atualizado após importação
A19: Importação | B19: Última Atualização | D19: Data | E19: Data da última importação
A20: Importação | B20: Total Registros | D20: Qtd | E20: Quantidade de registros importados

Sheet Mapeamento
A1: MAPEAMENTO DE CENTROS DE CUSTO E FORNECEDORES
A3: Grupo Financeiro | B3: Centro de Custo (Conta Azul) | C3: Fornecedor/Cliente | D3: Linha P&L | E3: Tipo | F3: Ativo | G3: Observações
A4: Receita Google | B4: Google Play Net Revenue | C4: GOOGLE BRASIL PAGAMENTOS LTDA | D4: 25 | E4: Receita | F4: Sim | G4: Receita Google Play
A5: Receita Apple | B5: App Store Net Revenue | C5: App Store (Apple) | D5: 33 | E5: Receita | F5: Sim | G5: Receita App Store
A6: Receita Brasil | B6: Google Play Net Revenue | C6: GOOGLE BRASIL PAGAMENTOS LTDA | D6: 26 | E6: Receita | F6: Sim | G6: Receita Brasil - Google
A7: Receita Brasil | B7: App Store Net Revenue | C7: App Store (Apple) | D7: 34 | E7: Receita | F7: Sim | G7: Receita Brasil - Apple
A8: Receita USA | B8: Google Play Net Revenue | C8: GOOGLE BRASIL PAGAMENTOS LTDA | D8: 28 | E8: Receita | F8: Sim | G8: Receita USA - Google
A9: Receita USA | B9: App Store Net Revenue | C9: App Store (Apple) | D9: 36 | E9: Receita | F9: Sim | G9: Receita USA - Apple
A11: COGS | B11: Web Services Expenses | C11: AWS | D11: 43 | E11: Custo | F11: Sim | G11: Amazon Web Services
A12: COGS | B12: Web Services Expenses | C12: Cloudflare | D12: 44 | E12: Custo | F12: Sim | G12: Cloudflare
A13: COGS | B13: Web Services Expenses | C13: Heroku | D13: 45 | E13: Custo | F13: Sim | G13: Heroku
A14: COGS | B14: Web Services Expenses | C14: IAPHUB | D14: 46 | E14: Custo | F14: Sim | G14: IAPHUB
A15: COGS | B15: Web Services Expenses | C15: MailGun | D15: 47 | E15: Custo | F15: Sim | G15: MailGun
... A36: Rendimentos | B36: Rendimentos de Aplicações | C36: BANCO INTER | D36: 38 | E36: Receita | F36: Sim | G36: Rendimentos - Banco Inter

Sheet Extrato_Importado
A1: EXTRATO CONTA AZUL - DADOS IMPORTADOS
A3: Data Competência | B3: Centro de Custo | C3: Fornecedor/Cliente | D3: Descrição | E3: Valor (R$) | F3: Tipo Operação | G3: Categoria | H3: Mês | I3: Grupo Mapeado | J3: Linha P&L
A4: 45901 | B4: Other Taxes | C4: BANCO INTER | D4: Ajuste de cota/precificação para alinhar ao extrato (valor bruto) | E4: 438.62 | F4: Crédito | G4: Ajuste de cotas | H4: 2025-09
A5: 45901 | B5: Marketing & Growth Expenses | D5: Jonatthan Marllon Espinola Reganham - Transferência | Pix | E5: -74 | F5: Débito | G5: Marketing e Publicidade - Sem NF | H5: 2025-09
A6: 45901 | B6: Rendimentos de Aplicações | C6: CONTA SIMPLES | D6: Rentabilidade CDI - Remuneração-Cta Pgto | E6: 5.7 | F6: Crédito | G6: Rendimentos de Aplicações | H6: 2025-09
A7: 45902 | B7: Rendimentos de Aplicações | C7: CONTA SIMPLES | D7: Rentabilidade CDI - Remuneração-Cta Pgto | E7: 23.9 | F7: Crédito | G7: Rendimentos de Aplicações | H7: 2025-09
A8: 45903 | B8: Rendimentos de Aplicações | C8: CONTA SIMPLES | D8: Rentabilidade CDI - Remuneração-Cta Pgto | E8: 23.4 | F8: Crédito | G8: Rendimentos de Aplicações | H8: 2025-09
A9: 45904 | B9: Rendimentos de Aplicações | C9: CONTA SIMPLES | D9: Rentabilidade CDI - Remuneração-Cta Pgto | E9: 24.83 | F9: Crédito | G9: Rendimentos de Aplicações | H9: 2025-09
A10: 45905 | D10: Pix enviado - Umatch Ltda | E10: 47610 | F10: Crédito | G10: Transferência de Entrada | H10: 2025-09
A11: 45905 | D11: Pix enviado - Umatch Ltda | E11: -47610 | F11: Débito | G11: Transferência de Saída | H11: 2025-09
A12: 45905 | B12: Marketing & Growth Expenses | D12: Higor Natan Costa Barbosa - Transferência | Pix | E12: -2564 | F12: Débito | G12: Marketing e Publicidade - Sem NF | H12: 2025-09
A13: 45905 | B13: Marketing & Growth Expenses | D13: GUSTAVO CRUZ SILVA - Transferência | Pix | E13: -1854 | F13: Débito | G13: Marketing e Publicidade - Sem NF | H13: 2025-09
A14: 45905 | B14: Marketing & Growth Expenses | D14: Alan Pereira dos Anjos - Transferência | Pix | E14: -1786 | F14: Débito | G14: Marketing e Publicidade - Sem NF | H14: 2025-09
A15: 45905 | B15: Marketing & Growth Expenses | D15: Rian da Silva Mascarenhas - Transferência | Pix | E15: -1602 | F15: Débito | G15: Marketing e Publicidade - Sem NF | H15: 2025-09
A16: 45905 | B16: Marketing & Growth Expenses | D16: Nataniele Cristian Nonato dos Anjos - Transferência | Pix | E16: -1372 | F16: Débito | G16: Marketing e Publicidade - Sem NF | H16: 2025-09
A17: 45905 | B17: Marketing & Growth Expenses | D17: Arthur de Queiros Alves - Transferência | Pix | E17: -1260 | F17: Débito | G17: Marketing e Publicidade - Sem NF | H17: 2025-09
A18: 45905 | B18: Marketing & Growth Expenses | D18: Dalva Alves Costa - Transferência | Pix | E18: -1240 | F18: Débito | G18: Marketing e Publicidade - Sem NF | H18: 2025-09
A19: 45905 | B19: Marketing & Growth Expenses | D19: Gabriel Santos de Freitas - Transferência | Pix | E19: -1178 | F19: Débito | G19: Marketing e Publicidade - Sem NF | H19: 2025-09
A20: 45905 | B20: Marketing & Growth Expenses | D20: Evellyn Alves Melo - Transferência | Pix | E20: -1096 | F20: Débito | G20: Marketing e Publicidade - Sem NF | H20: 2025-09
A21: 45905 | B21: Marketing & Growth Expenses | D21: Rafael Pimenta Vieira - Transferência | Pix | E21: -882 | F21: Débito | G21: Marketing e Publicidade - Sem NF | H21: 2025-09
A22: 45905 | B22: Marketing & Growth Expenses | D22: Nathalia Cristina Lucas Elias - Transferência | Pix | E22: -876 | F22: Débito | G22: Marketing e Publicidade - Sem NF | H22: 2025-09
A23: 45905 | B23: Marketing & Growth Expenses | D23: VALDIR PELIK CALAZANS - Transferência | Pix | E23: -1090 | F23: Débito | G23: Marketing e Publicidade - Sem NF | H23: 2025-09
... A101: 45905 | B101: Marketing & Growth Expenses | D101: Victoria Fonseca Moreira Silva - Transferência | Pix | E101: -2 | F101: Débito | G101: Marketing e Publicidade - Sem NF | H101: 2025-09
A102: 45905 | B102: Rendimentos de Aplicações | C102: CONTA SIMPLES | D102: Rentabilidade CDI | E102: 29.12 | F102: Crédito | G102: Rendimentos de Aplicações | H102: 2025-09
A103: 45906 | B103: Rendimentos de Aplicações | C103: CONTA SIMPLES | D103: Rentabilidade CDI - Remuneração-Cta Pgto | E103: 27.93 | F103: Crédito | G103: Rendimentos de Aplicações | H103: 2025-09
A104: 45907 | B104: Rendimentos de Aplicações | C104: CONTA SIMPLES | D104: Rentabilidade CDI - Remuneração-Cta Pgto | E104: 9.26 | F104: Crédito | G104: Rendimentos de Aplicações | H104: 2025-09
A105: 45908 | B105: Rendimentos de Aplicações | C105: CONTA SIMPLES | D105: Rentabilidade CDI | E105: 12.34 | F105: Crédito | G105: Rendimentos de Aplicações | H105: 2025-09
A106: 45908 | B106: Identificar | D106: PIX Enviado para KANAYAMA SUSHI LTDA | E106: -901.85 | F106: Débito | G106: Despesas a identificar | H106: 2025-09
A107: 45909 | B107: Rendimentos de Aplicações | C107: CONTA SIMPLES | D107: Rentabilidade CDI - Remuneração-Cta Pgto | E107: 30.73 | F107: Crédito | G107: Rendimentos de Aplicações | H107: 2025-09
A108: 45889 | B108: Travel | C108: American Airlines | D108: AMERICAN AIR* captureRe | E108: -12194.91 | F108: Débito | G108: Viagens e Representações | H108: 2025-08
A109: 45887 | B109: Tech Support & Services | C109: Adobe | D109: ADOBE | E109: -139 | F109: Débito | G109: Software / Licença de Uso | H109: 2025-08
A110: 45894 | B110: Tech Support & Services | C110: Adobe | D110: ADOBE | E110: -139 | F110: Débito | G110: Software / Licença de Uso | H110: 2025-08
A111: 45874 | B111: Tech Support & Services | C111: COMPANYHERO SAO PAULO BRA | D111: COMPANY HERO | E111: -136 | F111: Débito | G111: Software / Licença de Uso | H111: 2025-08
A112: 45881 | B112: Tech Support & Services | C112: ClickSign | D112: CLICK SIGN*Clicksign | E112: -39 | F112: Débito | G112: Software / Licença de Uso | H112: 2025-08
A113: 45899 | B113: Tech Support & Services | C113: Canva | D113: EBN*CANVA0462 | E113: -35 | F113: Débito | G113: Software / Licença de Uso | H113: 2025-08
A114: 45910 | D114: Origem: Conta Corrente - Banco Inter / Destino: Conta Corrente - Banco Stone | E114: 15170 | F114: Crédito | G114: Transferência de Entrada | H114: 2025-09
A115: 45910 | D115: Origem: Conta Corrente - Banco Inter / Destino: Conta Corrente - Banco Stone | E115: -15170 | F115: Débito | G115: Transferência de Saída | H115: 2025-09
A116: 45870 | B116: Payroll Tax - Brazil | C116: IMPOSTOS/TRIBUTOS | D116: DAMSP - DARF ISS 08.2025 | E116: -17 | F116: Débito | G116: Retenção - ISS Serviços Tomados | H116: 2025-08
A117: 45870 | B117: Legal & Accounting Expenses | C117: BHUB.AI | D117: NF 34182 - BHUB - MENSALIDADE BPO FINANCEIRO | E117: -3294.14 | F117: Débito | G117: Honorários BPO Financeiro | H117: 2025-08
A118: 45870 | B118: Legal & Accounting Expenses | C118: BHUB.AI | D118: NF 34182 - BHUB - MENSALIDADE CONTÁBIL | E118: -1251.77 | F118: Débito | G118: Honorários Contábeis | H118: 2025-08
...

Sheet DRE
A1: DEMONSTRAÇÃO DO RESULTADO DO EXERCÍCIO (DRE)
A3: Linha DRE | B3: Unidade | C3: 05/2024 | D3: 06/2024 | E3: 07/2024 | F3: 08/2024 | G3: 09/2024 | H3: 10/2024 | I3: 11/2024 | J3: 12/2024 | K3: 01/2025 | L3: 02/2025 | M3: 03/2025 | N3: 04/2025 | O3: 05/2025 | P3: 06/2025 | Q3: 07/2025 | R3: 08/2025 | S3: 09/2025 | T3: 10/2025
A5: RECEITA OPERACIONAL BRUTA | B5: BRL | C5: ='P&L'!C24 | D5: ='P&L'!D24 | E5: ='P&L'!E24 | F5: ='P&L'!F24 | G5: ='P&L'!G24 | H5: ='P&L'!H24 | I5: ='P&L'!I24 | J5: ='P&L'!J24 | ... T5: ='P&L'!T24
A6: Receita de Vendas (Google + Apple) | B6: BRL | C6: ='P&L'!C25 | D6: ='P&L'!D25 | E6: ='P&L'!E25 | F6: ='P&L'!F25 | G6: ='P&L'!G25 | H6: ='P&L'!H25 | I6: ='P&L'!I25 | J6: ='P&L'!J25 | ... T6: ='P&L'!T25
A7: Rendimentos de Aplicações | B7: BRL | C7: ='P&L'!C42 | D7: ='P&L'!D42 | E7: ='P&L'!E42 | F7: ='P&L'!F42 | G7: ='P&L'!G42 | H7: ='P&L'!H42 | I7: ='P&L'!I42 | J7: ='P&L'!J42 | ... T7: ='P&L'!T42
A9: (-) CUSTOS DIRETOS | B9: BRL | C9: ='P&L'!C44 | D9: ='P&L'!D44 | E9: ='P&L'!E44 | F9: ='P&L'!F44 | G9: ='P&L'!G44 | H9: ='P&L'!H44 | I9: ='P&L'!I44 | J9: ='P&L'!J44 | ... T9: ='P&L'!T44
A10: Payment Processing | B10: BRL | C10: ='P&L'!C45 | D10: ='P&L'!D45 | E10: ='P&L'!E45 | F10: ='P&L'!F45 | G10: ='P&L'!G45 | H10: ='P&L'!H45 | I10: ='P&L'!I45 | J10: ='P&L'!J45 | ... T10: ='P&L'!T45
A11: COGS (Custo dos Produtos Vendidos) | B11: BRL | C11: ='P&L'!C46 | D11: ='P&L'!D46 | E11: ='P&L'!E46 | F11: ='P&L'!F46 | G11: ='P&L'!G46 | H11: ='P&L'!H46 | I11: ='P&L'!I46 | J11: ='P&L'!J46 | ... T11: ='P&L'!T46
A13: (=) LUCRO BRUTO | B13: BRL | C13: ='P&L'!C54 | D13: ='P&L'!D54 | E13: ='P&L'!E54 | F13: ='P&L'!F54 | G13: ='P&L'!G54 | H13: ='P&L'!H54 | I13: ='P&L'!I54 | J13: ='P&L'!J54 | ... T13: ='P&L'!T54
A14: Margem Bruta (%) | B14: % | C14: ='P&L'!C55 | D14: ='P&L'!D55 | E14: ='P&L'!E55 | F14: ='P&L'!F55 | G14: ='P&L'!G55 | H14: ='P&L'!H55 | I14: ='P&L'!I55 | J14: ='P&L'!J55 | ... T14: ='P&L'!T55
A16: (-) DESPESAS OPERACIONAIS | B16: BRL | C16: ='P&L'!C57 | D16: ='P&L'!D57 | E16: ='P&L'!E57 | F16: ='P&L'!F57 | G16: ='P&L'!G57 | H16: ='P&L'!H57 | I16: ='P&L'!I57 | J16: ='P&L'!J57 | ... T16: ='P&L'!T57
A17: R&D | B17: BRL | C17: ='P&L'!C58 | D17: ='P&L'!D58 | E17: ='P&L'!E58 | F17: ='P&L'!F58 | G17: ='P&L'!G58 | H17: ='P&L'!H58 | I17: ='P&L'!I58 | J17: ='P&L'!J58 | ... T17: ='P&L'!T58
A18: SG&A | B18: BRL | C18: ='P&L'!C59 | D18: ='P&L'!D59 | E18: ='P&L'!E59 | F18: ='P&L'!F59 | G18: ='P&L'!G59 | H18: ='P&L'!H59 | I18: ='P&L'!I59 | J18: ='P&L'!J59 | ... T18: ='P&L'!T59
A19: Marketing | B19: BRL | C19: ='P&L'!C60 | D19: ='P&L'!D60 | E19: ='P&L'!E60 | F19: ='P&L'!F60 | G19: ='P&L'!G60 | H19: ='P&L'!H60 | I19: ='P&L'!I60 | J19: ='P&L'!J60 | ... T19: ='P&L'!T60
A20: Salários (Wages) | B20: BRL | C20: ='P&L'!C68 | D20: ='P&L'!D68 | E20: ='P&L'!E68 | F20: ='P&L'!F68 | G20: ='P&L'!G68 | H20: ='P&L'!H68 | I20: ='P&L'!I68 | J20: ='P&L'!J68 | ... T20: ='P&L'!T68
A21: Tech Support & Services | B21: BRL | C21: ='P&L'!C69 | D21: ='P&L'!D69 | E21: ='P&L'!E69 | F21: ='P&L'!F69 | G21: ='P&L'!G69 | H21: ='P&L'!H69 | I21: ='P&L'!I69 | J21: ='P&L'!J69 | ... T21: ='P&L'!T69
A23: (=) EBITDA | B23: BRL | C23: ='P&L'!C74 | D23: ='P&L'!D74 | E23: ='P&L'!E74 | F23: ='P&L'!F74 | G23: ='P&L'!G74 | H23: ='P&L'!H74 | I23: ='P&L'!I74 | J23: ='P&L'!J74 | ... T23: ='P&L'!T74
A24: Margem EBITDA (%) | B24: % | C24: ='P&L'!C76 | D24: ='P&L'!D76 | E24: ='P&L'!E76 | F24: ='P&L'!F76 | G24: ='P&L'!G76 | H24: ='P&L'!H76 | I24: ='P&L'!I76 | J24: ='P&L'!J76 | ... T24: ='P&L'!T76
A26: (=) RESULTADO OPERACIONAL (EBIT) | B26: BRL | C26: ='P&L'!C75 | D26: ='P&L'!D75 | E26: ='P&L'!E75 | F26: ='P&L'!F75 | G26: ='P&L'!G75 | H26: ='P&L'!H75 | I26: ='P&L'!I75 | J26: ='P&L'!J75 | ... T26: ='P&L'!T75
A28: INDICADORES-CHAVE
A29: NAU (Net Active Users) | B29: % | C29: ='P&L'!C5 | D29: ='P&L'!D5 | E29: ='P&L'!E5 | F29: ='P&L'!F5 | G29: ='P&L'!G5 | H29: ='P&L'!H5 | I29: ='P&L'!I5 | J29: ='P&L'!J5 | ... T29: ='P&L'!T5
A30: CPA (Cost Per Acquisition) | B30: % | C30: ='P&L'!C16 | D30: ='P&L'!D16 | E30: ='P&L'!E16 | F30: ='P&L'!F16 | G30: ='P&L'!G16 | H30: ='P&L'!H16 | I30: ='P&L'!I16 | J30: ='P&L'!J16 | ... T30: ='P&L'!T16
A31: Marketing / Revenue no Tax (%) | B31: % | C31: ='P&L'!C61 | D31: ='P&L'!D61 | E31: ='P&L'!E61 | F31: ='P&L'!F61 | G31: ='P&L'!G61 | H31: ='P&L'!H61 | I31: ='P&L'!I61 | J31: ='P&L'!J61 | ... T31: ='P&L'!T61

Sheet Dashboard
A1: DASHBOARD - INDICADORES E ANÁLISES
A3: KPIS PRINCIPAIS (Último Mês Disponível)
A5: Receita Total | B5: ='P&L'!T24
A6: EBITDA | B6: ='P&L'!T74
A7: Margem EBITDA | B7: ='P&L'!T76
A8: Gross Margin | B8: ='P&L'!T55
A9: NAU | B9: ='P&L'!T5
A10: CPA | B10: ='P&L'!T16
A13: RESUMO MENSAL (Últimos 6 Meses)
A15: Mês | B15: Receita | C15: COGS | D15: Gross Profit | E15: OpEx | F15: EBITDA | G15: Margem EBITDA
A16: ='P&L'!O3 | B16: ='P&L'!O24 | C16: ='P&L'!O44 | D16: ='P&L'!O54 | E16: ='P&L'!O57 | F16: ='P&L'!O74 | G16: ='P&L'!O76
A17: ='P&L'!P3 | B17: ='P&L'!P24 | C17: ='P&L'!P44 | D17: ='P&L'!P54 | E17: ='P&L'!P57 | F17: ='P&L'!P74 | G17: ='P&L'!P76
A18: ='P&L'!Q3 | B18: ='P&L'!Q24 | C18: ='P&L'!Q44 | D18: ='P&L'!Q54 | E18: ='P&L'!Q57 | F18: ='P&L'!Q74 | G18: ='P&L'!Q76
A19: ='P&L'!R3 | B19: ='P&L'!R24 | C19: ='P&L'!R44 | D19: ='P&L'!R54 | E19: ='P&L'!R57 | F19: ='P&L'!R74 | G19: ='P&L'!R76
A20: ='P&L'!S3 | B20: ='P&L'!S24 | C20: ='P&L'!S44 | D20: ='P&L'!S54 | E20: ='P&L'!S57 | F20: ='P&L'!S74 | G20: ='P&L'!S76
A21: ='P&L'!T3 | B21: ='P&L'!T24 | C21: ='P&L'!T44 | D21: ='P&L'!T54 | E21: ='P&L'!T57 | F21: ='P&L'!T74 | G21: ='P&L'!T76
A24: ANÁLISE DE CUSTOS (Último Mês)
A26: Payment Processing | B26: ='P&L'!T45 | C26: =='P&L'!T45/('P&L'!T24) | D26: % da Receita
A27: COGS Total | B27: ='P&L'!T46 | C27: =='P&L'!T46/('P&L'!T24) | D27: % da Receita
A28: Marketing | B28: ='P&L'!T60 | C28: =='P&L'!T60/('P&L'!T24) | D28: % da Receita
A29: Wages | B29: ='P&L'!T68 | C29: =='P&L'!T68/('P&L'!T24) | D29: % da Receita
A30: Tech Support | B30: ='P&L'!T69 | C30: =='P&L'!T69/('P&L'!T24) | D30: % da Receita

Sheet Glossário
A1: GLOSSÁRIO DE TERMOS E SIGLAS
A3: Termo/Sigla | B3: Nome Completo | C3: Definição
A4: NAU | B4: Net Active Users | C4: Número de usuários ativos líquidos no período
A5: MAU | B5: Monthly Active Users | C5: Número de usuários ativos mensais
A6: CPA | B6: Cost Per Acquisition | C6: Custo de aquisição por usuário (Marketing / NAU)
A7: ARPU | B7: Average Revenue Per User | C7: Receita média por usuário
A8: ARPPU | B8: Average Revenue Per Paying User | C8: Receita média por usuário pagante
A9: COGS | B9: Cost of Goods Sold | C9: Custo dos Produtos Vendidos (CMV) - custos diretos de infraestrutura
A10: SG&A | B10: Selling, General & Administrative | C10: Despesas de Vendas, Gerais e Administrativas
A11: EBITDA | B11: Earnings Before Interest, Taxes, Depreciation and Amortization | C11: Lucro antes de Juros, Impostos, Depreciação e Amortização
A12: EBIT | B12: Earnings Before Interest and Taxes | C12: Lucro antes de Juros e Impostos (Resultado Operacional)
A13: OpEx | B13: Operating Expenses | C13: Despesas Operacionais (R&D + SG&A)
A14: R&D | B14: Research & Development | C14: Pesquisa e Desenvolvimento
... A22: IAPHUB | B22: In-App Purchase Hub | C22: Plataforma de gerenciamento de compras in-app

Sheet Checklist
A1: CHECKLIST DE IMPLANTAÇÃO E USO
A3: Etapa | B3: Descrição | C3: Status | D3: Observações
A4: 1. Importação | B4: Importar extrato do Conta Azul (CSV) | C4: ✓ | D4: Dados já importados na aba Extrato_Importado
A5: 2. Mapeamento | B5: Revisar e ajustar mapeamento de centros de custo | C5: ⚠ | D5: Verificar aba Mapeamento e adicionar novos fornecedores se necessário
A6: 3. Parâmetros | B6: Configurar parâmetros editáveis | C6: ⚠ | D6: Preencher campos amarelos na aba Inputs
A7: 4. Validação P&L | B7: Validar cálculos automáticos do P&L | C7: ⚠ | D7: Verificar se valores importados estão corretos
A8: 5. Validação DRE | B8: Validar DRE consolidado | C8: ⚠ | D8: Conferir totalizações e margens
A9: 6. Dashboard | B9: Analisar KPIs e indicadores | C9: ⚠ | D9: Revisar gráficos e métricas principais
A10: 7. Documentação | B10: Documentar premissas e ajustes | C10: ⚠ | D10: Registrar observações na aba Inputs
A11: 8. Backup | B11: Salvar cópia de segurança | C11: ⚠ | D11: Manter versões anteriores para auditoria
A14: INSTRUÇÕES DE USO:
A15: 1. Exportar extrato do Conta Azul em formato CSV
A16: 2. Substituir dados na aba Extrato_Importado (copiar e colar)
A17: 3. Verificar se novos fornecedores/clientes precisam ser mapeados na aba Mapeamento
A18: 4. Preencher campos editáveis (amarelos) na aba Inputs conforme necessário
A19: 5. As fórmulas do P&L e DRE são atualizadas automaticamente
A20: 6. Revisar Dashboard para análise de tendências e KPIs
A21: 7. Campos não importados podem ser preenchidos manualmente no P&L
